import os 
import sys
import numpy as np 
import pandas as pd

from src.exception import CustomException
from src.logger import logging
import dill

def save_object(file_path, obj):
    try:
        dir_path = os.path.dirname(file_path)
        os.makedirs(dir_path, exist_ok=True)
        with open(file_path, 'wb') as f:
            dill.dump(obj, f)
            logging.info(f"Object saved at: {file_path}")

    except Exception as e:
        logging.error(f"Error occurred while saving object: {e}")
        raise CustomException(e, sys)